Workbook

Sheet JANUARI
A1: BARANG MASUK ARAW FILM | K1: BON JATUH TEMPO MEI 2021 ( JT)
A2: TGL MASUK | B2: NAMA BARANG | C2: SUPLIER | D2: QTY | E2: SAT | F2: HARGA/PCS/SET | G2: JUMLAH | H2: TOTAL FAKTUR | I2: KET | K2: NO | L2: TGL BARANG MASUK | M2: NAMA SALES/ SUPLIER | N2: JUMLAH BON | O2: KET
A3: 44198 | B3: SARUNG JOK INNOVA LUXURY MB 8808 | C3: B'IDA | D3: 1 | E3: SET | K3: 1 | L3: 44158 | M3: PB.IRWAN | N3: 4000000 | O3: GIRO 25/5/21
B4: SARUNG JOK INNOVA LUXURY MB 9001 +9010 | C4: B'IDA | D4: 1 | E4: SET | K4: 2 | L4: 44161 | M4: PB.IRWAN | N4: 1800000 | O4: GIRO 25/5/21
A5: 44200 | B5: FRONT GUARD (PLANG DEPAN) PAJERO '19 RHINO | C5: TJM | D5: 1 | E5: SET | F5: 2150000 | G5: =F5*D5 -> 2150000 | H5: =SUM(G5) -> 2150000 | I5: JUNI | J5: LUNAS TF 30/1 | K5: 3 | L5: 44163 | M5: PB.LEO | N5: 11700000 | O5: GIRO 15/5/21
A6: 44200 | B6: TALANG AIR H-TECH HITAM ALL NEW PAJERO'16 D/T | C6: MR.BOSS | D6: 5 | E6: SET | F6: 123000 | G6: =F6*D6 -> 615000 | H6: =SUM(G6) -> 615000 | I6: MEI | J6: LUNAS TF.6/4/21 | K6: 4 | L6: 44166 | M6: MR.BOSS | N6: 1040000 | O6: GIRO 20/5/21
A7: 44200 | B7: OUTER COVER ELEGANT BLACKTIVO JAZZ | C7: JSL | D7: 5 | E7: SET | F7: 135000 | G7: =F7*D7 -> 675000 | H7: =SUM(G7:G9) -> 2675000 | I7: RENCANA CASH BLN MARET | K7: 5 | L7: 44166 | M7: MR.BOSS | N7: 1235000 | O7: GIRO 20/5/21
B8: HANDLE COVER BLACKTIVO JAZZ | C8: JSL | D8: 5 | E8: SET | F8: 100000 | G8: =F8*D8 -> 500000 | K8: 6 | L8: 44166 | M8: MR.BOSS | N8: 1570000 | O8: GIRO 20/5/21
B9: SIDE SCUFF PLATE ACTIVO SPORTY W/LAMP AN RUSH | C9: JSL | D9: 5 | E9: SET | F9: 300000 | G9: =F9*D9 -> 1500000 | K9: 7 | L9: 44167 | M9: HENDRIK | N9: 1800000 | O9: GIRO 10/5/21
A10: 44204 | B10: STRETCHER AMBULANCE YDC 3B | C10: GM | D10: 1 | E10: SET | G10: =F10*D10 -> 0 | I10: LUNAS | K10: 8 | L10: 44172 | M10: MR.BOSS | N10: 750000 | O10: GIRO 20/5/21
A11: 44204 | B11: SARUNG JOK RUSH'20 MB 9001 + 9005 | C11: B'IDA | D11: 1 | E11: SET | G11: =F11*D11 -> 0 | K11: 9 | L11: 44172 | M11: MR.BOSS | N11: 2250000 | O11: GIRO 20/5/21
B12: SARUNG JOK XPANDER MB 9001 + 9008 | C12: B'IDA | D12: 1 | E12: SET | G12: =F12*D12 -> 0 | K12: 10 | L12: 44172 | M12: HENDRIK | N12: 3050000 | O12: GIRO 10/5/21
A13: 44205 | B13: BALANCE ARM FORTUNER MERAH | C13: IRWAN | D13: 2 | E13: SET | F13: 1800000 | G13: =F13*D13 -> 3600000 | H13: =SUM(G13:G19) -> 22900000 | I13: JUNI | J13: 44292 | K13: 11 | L13: 44173 | M13: PB.IRWAN | N13: 12515000 | O13: GIRO 25/5/21
B14: LIS GRILL HITAM BRIO'20 ORI | C14: IRWAN | D14: 15 | E14: SET | F14: 200000 | G14: =F14*D14 -> 3000000 | K14: 13 | L14: 44176 | M14: PB.IRWAN | N14: 15000000 | O14: GIRO 25/5/21
B15: SPOILER BRIO MERAH | C15: IRWAN | D15: 10 | E15: SET | F15: 400000 | G15: =F15*D15 -> 4000000 | K15: 14 | L15: 44177 | M15: SALIM (MOBILINDO) | N15: 4760000 | O15: GIRO 30/5/21
B16: SPOILER BRIO PUTIH | C16: IRWAN | D16: 6 | E16: SET | F16: 400000 | G16: =F16*D16 -> 2400000 | K16: 15 | L16: 44181 | M16: SALIM (MOBILINDO) | N16: 2375000 | O16: GIRO 30/5/21
B17: SPOILER BRIO SILVER | C17: IRWAN | D17: 5 | E17: SET | F17: 400000 | G17: =F17*D17 -> 2000000 | K17: 16 | L17: 44181 | M17: SALIM (MOBILINDO) | N17: 6300000 | O17: GIRO 30/5/21
B18: SPOILER BRIO HITAM | C18: IRWAN | D18: 4 | E18: SET | F18: 400000 | G18: =F18*D18 -> 1600000 | K18: 17 | L18: 44182 | M18: JKI | N18: 4400000 | O18: GIRO 30/5/21
B19: FOGLAMP BRIO DLAA | C19: IRWAN | D19: 12 | E19: SET | F19: 525000 | G19: =F19*D19 -> 6300000 | K19: 18 | L19: 44186 | M19: MR.BOSS | N19: 8920000 | O19: GIRO 15/5/21
A20: 44205 | B20: KARPET MI 3 RAY BLACK GREY | C20: MR.BOSS | D20: 2 | E20: SET | F20: 425000 | G20: =F20*D20 -> 850000 | H20: =SUM(G20:G22) -> 4400000 | I20: JUNI | J20: 44292 | K20: 19 | L20: 44191 | M20: HENDRIK | N20: 9630000 | O20: GIRO 30/5/21
B21: KARPET MI 3 RAY COFFE BEIGE | C21: MR.BOSS | D21: 5 | E21: SET | F21: 425000 | G21: =F21*D21 -> 2125000 | K21: 20 | L21: 44195 | M21: SALIM (MOBILINDO) | N21: 4000000 | O21: GIRO 30/5/21
B22: KARPET MI 2 RAY BLACK GREY | C22: MR.BOSS | D22: 5 | E22: SET | F22: 285000 | G22: =F22*D22 -> 1425000 | K22: 21 | L22: 44200 | M22: MR.BOSS | N22: 615000 | O22: LUNAS 06/04/2021
A23: 44205 | B23: GARNIS LAMPU DEPAN HILUX'20 HITAM WITH LOGO | C23: HENDRIK | D23: 3 | E23: SET | F23: 175000 | G23: =F23*D23 -> 525000 | H23: =SUM(G23:G28) -> 4025000 | I23: JUNI TGL 10 | J23: 44249 | K23: 22 | L23: 44214 | M23: NVM | N23: 1110000 | O23: LUNAS TF 15/2
B24: GARNIS LAMPU BELAKANG HILUX'20 HITAM WITH LOGO | C24: HENDRIK | D24: 3 | E24: SET | F24: 175000 | G24: =F24*D24 -> 525000 | K24: 23 | L24: 44216 | M24: NVM(HANDOYO) | N24: 3660000 | O24: GIRO 30/5/21
B25: GARNIS LAMPU DEPAN RUSH'18 HITAM | C25: HENDRIK | D25: 5 | E25: SET | F25: 135000 | G25: =F25*D25 -> 675000 | K25: 24 | L25: 44231 | M25: HENDRIK | N25: 10800000 | O25: GIRO 30/5/21
B26: GARNIS LAMPU BELAKANG RUSH'18 HITAM | C26: HENDRIK | D26: 5 | E26: SET | F26: 150000 | G26: =F26*D26 -> 750000 | K26: 25 | L26: 44249 | M26: KO AKHON | N26: 7350000 | O26: LUNAS TF. 18/5/21
B27: GARNIS LAMPU DEPAN PAJERO'18 HITAM | C27: HENDRIK | D27: 5 | E27: SET | F27: 135000 | G27: =F27*D27 -> 675000 | K27: 26 | L27: 44250 | M27: TJM | N27: 2150000 | O27: LUNAS TF. 18/5/21
B28: GARNIS LAMPU BELAKANG PAJERO'18 HITAM | C28: HENDRIK | D28: 5 | E28: SET | F28: 175000 | G28: =F28*D28 -> 875000 | K28: 27 | L28: 44263 | M28: OTO PROJECT | N28: 4374000 | O28: LUNAS TF. 29/4/21
A29: 44205 | B29: KACA FILM WB 70i+ (1809200207K2A1) | C29: WINCOS | D29: 1 | E29: ROL | G29: =F29*D29 -> 0 | K29: 28 | L29: 44322 | M29: HENDRIK | N29: 3750000 | O29: LUNAS TF.18/5/21
A30: 44207 | B30: TOWING BELAKANG MCC (PLANG BELAKANG) PAJERO | C30: NVM | D30: 4 | E30: SET | F30: 1250000 | G30: =F30*D30 -> 5000000 | H30: =G30 -> 5000000 | I30: APRIL | J30: 44242 | K30: 29 | L30: 44343 | M30: HENDRIK | N30: 3750000 | O30: LUNAS TF. 01/6/21
A31: 44209 | B31: TV ANDROID 10' ENIGMA | C31: SALIM(MOBILINDO) | D31: 3 | E31: SET | F31: 2000000 | G31: =F31*D31 -> 6000000 | H31: =G31 -> 6000000 | I31: JUNI | J31: 44256
A32: 44211 | B32: SARUNG JOK G.AVANZA '20 HITAM | C32: B'IDA | D32: 2 | E32: SET | G32: =F32*D32 -> 0
B33: SARUNG JOK G.AVANZA '20 HITAM/GREY | C33: B'IDA | D33: 1 | E33: SET | G33: =F33*D33 -> 0 | N33: =SUM(N3:N32) -> 134654000
B34: SARUNG JOK G.AVANZA '20 HITAM/MERAH | C34: B'IDA | D34: 1 | E34: SET | G34: =F34*D34 -> 0
B35: SARUNG JOK G.AVANZA '20 HITAM/COKLAT | C35: B'IDA | D35: 1 | E35: SET | G35: =F35*D35 -> 0
B36: SARUNG JOK RUSH'20 HITAM | C36: B'IDA | D36: 2 | E36: SET | G36: =F36*D36 -> 0
B37: SARUNG JOK CALYA '20 HITAM | C37: B'IDA | D37: 2 | E37: SET | G37: =F37*D37 -> 0
B38: SARUNG JOK BRIO '20 HITAM | C38: B'IDA | D38: 2 | E38: SET | G38: =F38*D38 -> 0
B39: SARUNG JOK BRIO '20 HITAM/GREY | C39: B'IDA | D39: 1 | E39: SET | G39: =F39*D39 -> 0
B40: SARUNG JOK BRIO '20 HITAM/MERAH | C40: B'IDA | D40: 1 | E40: SET | G40: =F40*D40 -> 0
...

Sheet FEBRUARI
A1: BARANG MASUK ARAW FILM
A2: TGL MASUK | B2: NAMA BARANG | C2: SUPLIER | D2: QTY | E2: SAT | F2: HARGA/PCS/SET | G2: JUMLAH | H2: TOTAL FAKTUR | I2: KET | M2: BON JATUH TEMPO JUNI 2021 ( JT)
A3: 44228 | B3: KARPET KARET 3PC HITAM | C3: HERMAN | D3: 6 | E3: SET | F3: 145000 | G3: =F3*D3 -> 870000 | H3: =SUM(G3) -> 870000 | I3: JUNI | J3: 44250 | M3: NO | N3: TGL BARANG MASUK | O3: NAMA SALES/ SUPLIER | P3: JUMLAH BON | Q3: KET
A4: 44228 | B4: KARPET DASAR AGYA BLACK | C4: NVM | D4: 10 | E4: SET | F4: 170000 | G4: =F4*D4 -> 1700000 | H4: =SUM(G4:G5) -> 3400000 | I4: APRIL | J4: 44242 | M4: 1 | N4: 44196 | O4: IRWAN | P4: 6175000 | Q4: GIRO 15/06/2021 | R4: V | T4: =P11+P15+P16 -> 36626000 | U4: 3463
B5: KARPET DASAR BRIO BLACK | C5: NVM | D5: 10 | E5: SET | F5: 170000 | G5: =F5*D5 -> 1700000 | M5: 2 | N5: 44200 | O5: TJM | P5: 2150000 | Q5: LUNAS TF 4/6/2021 | U5: 4410
A6: 44228 | B6: AVANZA/AGYA/AYLA OUTER CHROME | C6: JSL | D6: 10 | E6: SET | F6: TITIPAN | M6: 3 | N6: 44205 | O6: IRWAN | P6: 22900000 | Q6: GIRO 30/06/2021 | S6: =P6+P9+P13+P21+P12 -> 41770000 | U6: 2450
B7: MOBILIO/BRIO/BRV'16 HANDLE HITAM | C7: JSL | D7: 10 | E7: SET | F7: 70000 | G7: =F7*D7 -> 700000 | H7: =SUM(G7:G8) -> 2700000 | I7: JULI | J7: 44275 | M7: 4 | N7: 44205 | O7: MR.BOSS | P7: 4400000 | Q7: GIRO 12/6/2021 | R7: V | T7: =P7+P14 -> 4815000 | U7: 5040
B8: BRIO'18 SCUFF PLATE ACTIVO W/REFLECTOR | C8: JSL | D8: 10 | E8: SET | F8: 200000 | G8: =F8*D8 -> 2000000 | M8: 5 | N8: 44205 | O8: HENDRIK | P8: 4025000 | Q8: GIRO 10/6/2021 | R8: V | U8: 6100
B9: RUSH/TERIOS/AVANZA/XENIA'19 MIROR COVER BLACK | C9: JSL | D9: 5 | E9: SET | F9: 100000 | G9: =F9*D9 -> 500000 | H9: =SUM(G9) -> 500000 | M9: 6 | N9: 44209 | O9: SALIM (MOBILINDO) | P9: 6000000 | Q9: GIRO 30/6/2021 | U9: 5360
A10: 44229 | B10: KARPET DASAR BRIO TIPIS | C10: IRWAN | D10: 100 | E10: SET | F10: 160000 | G10: =F10*D10 -> 16000000 | H10: =SUM(G10:G15) -> 19801200 | I10: JULI | J10: 44292 | M10: 7 | N10: 44531 | O10: HENDRIK | P10: 4050000 | Q10: LUNAS | U10: 3778
B11: KARPET KARET SMOKE TRANSPARAN | C11: IRWAN | D11: 4 | E11: SET | F11: 225000 | G11: =F11*D11 -> 900000 | M11: 8 | N11: 44212 | O11: JSL | P11: 10323000 | Q11: GIRO 15/6/21 | R11: V | T11: =P11+P15+P16 -> 36626000 | U11: 3775
B12: FIRE STOP (RACUN API) | C12: IRWAN | D12: 12 | E12: SET | F12: 20000 | G12: =F12*D12 -> 240000 | M12: 9 | N12: 44212 | O12: IRWAN | P12: 3200000 | Q12: GIRO 30/06/2021 | S12: =S6+R39 -> 100381000 | U12: 2250
B13: LAMPU SOROT ATAP 90CM | C13: IRWAN | D13: 1 | E13: SET | F13: 900000 | G13: =F13*D13 -> 900000 | M13: 10 | N13: 44249 | O13: NVM | P13: 6250000 | Q13: GIRO 30/6/21 | T13: =P13+P21 -> 9670000
B14: LAMPU SOROT ATAP 110CM | C14: IRWAN | D14: 1 | E14: SET | F14: 950000 | G14: =F14*D14 -> 950000 | M14: 11 | N14: 44214 | O14: MR.BOSS | P14: 415000 | Q14: GIRO 12/6/2021 | R14: V | U14: =SUM(U4:U13) -> 36626
B15: DAUBLE TIPE HIJAU | C15: IRWAN | D15: 208 | E15: SET | F15: 3900 | G15: =F15*D15 -> 811200 | M15: 12 | N15: 44214 | O15: JSL | P15: 16500000 | Q15: GIRO 15/6/21 | R15: V | T15: =SUM(P13+P21) -> 9670000
A16: 44231 | B16: HANDLE AVANZA VELOZ HITAM | C16: HENDRIK | D16: 5 | E16: SET | F16: 75000 | G16: =F16*D16 -> 375000 | H16: =SUM(G16:G29) -> 10800000 | I16: MEI | J16: 44249 | M16: 13 | N16: 44219 | O16: JSL | P16: 9803000 | Q16: GIRO 15/6/21 | R16: V
B17: HANDLE DEPAN HRV KEYLESS HITAM | C17: HENDRIK | D17: 5 | E17: SET | F17: 65000 | G17: =F17*D17 -> 325000 | M17: 14 | N17: 44219 | O17: JKI | P17: 2200000 | Q17: LUNAS TF. 01/7/21
B18: HANDLE PAJERO'16 HITAM | C18: HENDRIK | D18: 10 | E18: SET | F18: 110000 | G18: =F18*D18 -> 1100000 | M18: 15 | N18: 44222 | O18: PB.HERMAN | P18: 4500000 | Q18: GIRO 18/6/2021 | R18: V | S18: =SUM(P7+P14+P22) -> 6415000 | U18: 44252
B19: HANDLE BRIO HITAM | C19: HENDRIK | D19: 20 | E19: SET | F19: 80000 | G19: =F19*D19 -> 1600000 | M19: 16 | N19: 44249 | O19: NVM | P19: 1050000 | Q19: CASH 31/8/21
B20: TANKI HRV HITAM | C20: HENDRIK | D20: 5 | E20: SET | F20: 40000 | G20: =F20*D20 -> 200000 | M20: 17 | N20: 44228 | O20: HERMAN | P20: 870000 | Q20: GIRO 18/6/2021 | R20: V | S20: =P7+P14 -> 4815000 | U20: 44252
B21: TANKI BRIO HITAM | C21: HENDRIK | D21: 15 | E21: SET | F21: 35000 | G21: =F21*D21 -> 525000 | M21: 18 | N21: 44259 | O21: NVM | P21: 3420000 | Q21: GIRO 30/6/21
B22: TANKI RUSH HITAM | C22: HENDRIK | D22: 10 | E22: SET | F22: 40000 | G22: =F22*D22 -> 400000 | M22: 20 | N22: 44249 | O22: MR.BOSS | P22: 1600000 | Q22: GIRO 30/6/21 | R22: V
B23: . | C23: HENDRIK | D23: 15 | E23: SET | F23: 35000 | G23: =F23*D23 -> 525000 | M23: 21 | N23: 44316 | O23: WINCOS | P23: 30800000 | Q23: LUNAS 28/6/21
B24: HANDLE OUTER BELAKANG HRV HITAM (2PCS) | C24: HENDRIK | D24: 5 | E24: SET | F24: 75000 | G24: =F24*D24 -> 375000 | T24: 1-15 juni
B25: HANDLE OUTER BELAKANG HRV HITAM (6PCS) | C25: HENDRIK | D25: 5 | E25: SET | F25: 125000 | G25: =F25*D25 -> 625000 | P25: =SUM(P4:P24) -> 140631000 | Q25: total | T25: 6175000 | U25: herman
B26: OUTER BRIO HITAM | C26: HENDRIK | D26: 20 | E26: SET | F26: 100000 | G26: =F26*D26 -> 2000000 | T26: 4025000 | U26: hendrik
B27: OUTER INNOVA'16 CHROME | C27: HENDRIK | D27: 10 | E27: SET | F27: 125000 | G27: =F27*D27 -> 1250000 | P27: =P4+P6+P7+P8+P9+P11+P12+P13+P14+P15+P16+P18+P20+P21+P22 -> 100381000 | Q27: giro | T27: 36626000 | U27: jsl
B28: GARNIS LAMPU DEPAN HRV'20 HITAM | C28: HENDRIK | D28: 5 | E28: SET | F28: 140000 | G28: =F28*D28 -> 700000 | T28: 4815000 | U28: mr.boss
B29: GARNIS LAMPU BELAKANG HRV'20 HITAM | C29: HENDRIK | D29: 5 | E29: SET | F29: 160000 | G29: =F29*D29 -> 800000 | P29: =P5+P10+P23 -> 37000000 | Q29: lunas tf
A30: 44232 | B30: KACA FILM SRC 60-BLACK (ANTI GORES 60% SLR) | C30: JKI | D30: 2 | E30: ROL | F30: 1100000 | G30: =F30*D30 -> 2200000 | H30: =G30 -> 2200000 | I30: JULI | J30: LUNAS TF 14/8
A31: 44232 | B31: KACA FILM 4 MILI IR XT BLACK05 (KF CPF1 BLACK SECURITY 80%) | C31: JKI | D31: 1 | E31: ROL | F31: 9900000 | G31: =F31*D31 -> 9900000 | H31: =G31 -> 9900000 | P31: =P17+P19 -> 3250000 | Q31: blm bayar | T31: =SUM(T25:T30) -> 51641000 | V31: 60000000
A32: 44232 | B32: HOOD MOLDING INNOVA'16 | C32: JSL | D32: 3 | E32: PCS | F32: 110000 | G32: =F32*D32 -> 330000 | H32: =G32 -> 330000 | I32: JULI | J32: 44275 | V32: =V31-T31 -> 8359000
B33: OUTER BRIO HITAM | C33: JSL | D33: 10 | E33: SET | F33: 85000 | G33: =F33*D33 -> 850000 | H33: =G33 -> 850000 | I33: JULI | J33: 44275 | O33: GIRO YG DIBYR 60JT | P33: =P4+P7+P8+P11+P14+P15+P16+P18+P20+P22 -> 58611000 | Q33: V(ceklis) | R33: =T31+T35+T37 -> 58611000 | T33: 16-30 | V33: =V31-P33 -> 1389000
A34: 44233 | B34: SARUNG JOK RUSH 2021 (MB 9001 BLACK) | C34: B'IDA | D34: 1 | E34: SET | G34: =F34*D34 -> 0 | T34: 6000000 | U34: mobilindo
A35: 44235 | B35: HANDLE RUSH'18 SMARTKEY HITAM | C35: IRWAN | D35: 5 | E35: SET | F35: 85000 | G35: =F35*D35 -> 425000 | H35: =SUM(G35:G41) -> 2985000 | I35: JULI | J35: 44292 | T35: 5370000 | U35: herman
B36: SILICON KUNCI PAJERO'16 HITAM | C36: IRWAN | D36: 10 | E36: SET | F36: 18000 | G36: =F36*D36 -> 180000 | T36: 26100000 | U36: irwan
B37: SILICON KUNCI BRIO HITAM | C37: IRWAN | D37: 10 | E37: SET | F37: 18000 | G37: =F37*D37 -> 180000 | T37: 1600000 | U37: mr.boss
B38: COVER MITSUBISHI XPANDER HITAM D/B | C38: IRWAN | D38: 5 | E38: SET | F38: 130000 | G38: =F38*D38 -> 650000 | R38: =T31+T35 -> 57011000 | T38: 9670000 | U38: handoyo
B39: COVER MITSUBISHI XPANDER MERAH D/B | C39: IRWAN | D39: 5 | E39: SET | F39: 130000 | G39: =F39*D39 -> 650000 | R39: =R38+T37 -> 58611000
B40: DOOR GUARD BRAVO TOYOTA HITAM | C40: IRWAN | D40: 10 | E40: SET | F40: 45000 | G40: =F40*D40 -> 450000 | V40: =P6+P9+P12+P13+P21 -> 41770000
...

Sheet MARET
A1: BARANG MASUK ARAW FILM | L1: BON JATUH TEMPO JULI 2021 ( JT)
A2: TGL MASUK | B2: NAMA BARANG | C2: SUPLIER | D2: QTY | E2: SAT | F2: HARGA/PCS/SET | G2: JUMLAH | H2: TOTAL FAKTUR | I2: KET | L2: NO | M2: TGL BARANG MASUK | N2: NAMA SALES/ SUPLIER | O2: JUMLAH BON | P2: KET
A3: 44256 | B3: SARUNG JOK BRIO HITAM MERAH | C3: NVM | D3: 2 | E3: SET | F3: 600000 | G3: =F3*D3 -> 1200000 | H3: =SUM(G3:G7) -> 3800000 | I3: GIRO 30/7/21 | L3: 1 | M3: 44226 | N3: MR. BOSS | O3: 780000 | P3: CHAS | U3: 44226 | V3: MR. BOSS | W3: 780000
B4: SARUNG JOK BRIO HITAM CREAM | C4: NVM | D4: 1 | E4: SET | F4: 600000 | G4: =F4*D4 -> 600000 | L4: 2 | M4: 44228 | N4: JSL | O4: 3200000 | P4: GIRO 15/7/21 | Q4: =O4+O8+O9+O11 -> 4930000 | R4: 2700
B5: SARUNG JOK BRIO HITAM PUTIH | C5: NVM | D5: 1 | E5: SET | F5: 600000 | G5: =F5*D5 -> 600000 | L5: 3 | M5: 44229 | N5: IRWAN | O5: 19801200 | P5: GIRO 30/7/21 | R5: 500
B6: SARUNG JOK RUSH HITAM MERAH | C6: NVM | D6: 1 | E6: SET | F6: 700000 | G6: =F6*D6 -> 700000 | L6: 4 | M6: 44232 | N6: JKI | O6: 2200000 | P6: LUNAS TF. 25/8/21 | R6: 330
B7: SARUNG JOK RUSH HITAM CREAM | C7: NVM | D7: 1 | E7: SET | F7: 700000 | G7: =F7*D7 -> 700000 | L7: 5 | M7: 44232 | N7: JKI | O7: 9900000 | P7: LUNAS TF TGL 14/8/21 | R7: 550
A8: 44256 | B8: GARNIS LAMPU DEPAN HRV'18 CHROME | C8: HENDRIK | D8: 2 | E8: SET | F8: 140000 | G8: =F8*D8 -> 280000 | H8: =SUM(G8:G12) -> 4150000 | I8: JULI | L8: 6 | M8: 44232 | N8: JSL | O8: 330000 | P8: GIRO 15/7/21 | R8: 850
B9: GARNIS LAMPU BELAKANG HRV'18 CHROME | C9: HENDRIK | D9: 2 | E9: SET | F9: 160000 | G9: =F9*D9 -> 320000 | L9: 7 | M9: 44232 | N9: JSL | O9: 850000 | P9: GIRO 15/7/21
B10: GARNIS LAMPU DEPAN HRV'18 BLACKDOFF | C10: HENDRIK | D10: 5 | E10: SET | F10: 140000 | G10: =F10*D10 -> 700000 | L10: 8 | M10: 44235 | N10: IRWAN | O10: 2985000 | P10: GIRO 30/7/21 | R10: =SUM(R4:R9) -> 4930
B11: GARNIS LAMPU DEPAN RUSH'18 BLACKDOFF | C11: HENDRIK | D11: 10 | E11: SET | F11: 135000 | G11: =F11*D11 -> 1350000 | L11: 9 | M11: 44239 | N11: JSL | O11: 550000 | P11: GIRO 15/7/21 | S11: =O12+O13 -> 6000000
B12: GARNIS LAMPU BELAKANG RUSH'18 BLACKDOFF | C12: HENDRIK | D12: 10 | E12: SET | F12: 150000 | G12: =F12*D12 -> 1500000 | L12: 10 | M12: 44239 | N12: HERMAN | O12: 3500000 | P12: GIRO 30/7/21 | R12: =O4+O8+O9+O11 -> 4930000
A13: 44257 | B13: FOGLAMP BRIO'18 (DRL) | C13: JSL | D13: 6 | E13: SET | F13: 400000 | G13: =F13*D13 -> 2400000 | H13: =SUM(G13) -> 2400000 | I13: AGUSTUS | J13: 44275 | L13: 11 | M13: 44247 | N13: HERMAN | O13: 2500000 | P13: GIRO 30/7/21 | R13: =SUM(O5+O10) -> 22786200
A14: 44258 | B14: KARPET MI 2 RAY ABU HITAM | C14: HERMAN | D14: 3 | E14: SET | F14: 285000 | G14: =F14*D14 -> 855000 | H14: =SUM(G14:G15) -> 1710000 | I14: GIRO AGUSTUS | L14: 12 | M14: 44249 | N14: NVM | O14: 21550000 | P14: GIRO 30/7/21
B15: KARPET MI 2 RAY CREAM COKLAT | C15: HERMAN | D15: 3 | E15: SET | F15: 285000 | G15: =F15*D15 -> 855000 | L15: 13 | M15: 44256 | N15: NVM | O15: 3800000 | P15: GIRO 30/7/21 | Q15: =SUM(O14+O15) -> 25350000 | T15: =SUM(O6:O7) -> 12100000
A16: 44258 | B16: KACA FILM SRC 80 BLACK (AG 80%) | C16: JKI | D16: 2 | E16: ROL | F16: 1100000 | G16: =F16*D16 -> 2200000 | H16: =SUM(G16) -> 2200000 | I16: AGUSTUS | L16: 14 | M16: 44260 | N16: ROYAL CITY | O16: 6000000 | P16: GIRO 30/7/21 | Q16: =O16+O18 -> 11403000 | R16: =SUM(O16+O18) -> 11403000
A17: 44259 | B17: TANKI INNOVA HITAM | C17: HENDRIK | D17: 5 | E17: SET | F17: 40000 | G17: =F17*D17 -> 200000 | H17: =SUM(G17:G28) -> 5820000 | I17: AGUSTUS | J17: 44301 | L17: 15 | M17: 44256 | N17: HENDRIK | O17: 4150000 | P17: GIRO 30/7/21
B18: OUTER INNOVA HITAM | C18: HENDRIK | D18: 5 | E18: SET | F18: 125000 | G18: =F18*D18 -> 625000 | J18: DI TAMBAH + DIFFUSER 13 SET (4.225.000) TOTAL Rp 10.045.000 | L18: 16 | M18: 44280 | N18: ROYAL CITY | O18: 5403000 | P18: GIRO 30/7/21 | R18: =SUM(O12:O13) -> 6000000
B19: HANDLE INNOVA HITAM | C19: HENDRIK | D19: 5 | E19: SET | F19: 110000 | G19: =F19*D19 -> 550000 | L19: 17 | M19: 44295 | N19: TJM | O19: 4300000 | P19: LUNAS 28/7/21
B20: TANKI YARIS'18 HITAM | C20: HENDRIK | D20: 3 | E20: SET | F20: 40000 | G20: =F20*D20 -> 120000 | L20: 18 | M20: 44355 | N20: OTOPROJECT | O20: 7999000 | P20: LUNAS TF. 12/8/21
A21: TITIPAN | B21: GARNIS LAMPU DEPAN RUSH'18 BLACKDOFF | C21: HENDRIK | D21: 10 | E21: SET | G21: =F21*D21 -> 0 | L21: 19 | M21: 44261 | N21: GREAT | O21: 7250000 | P21: LUNAS 29/7/21
A22: TITIPAN | B22: GARNIS LAMPU BELAKANG RUSH'18 BLACKDOFF | C22: HENDRIK | D22: 10 | E22: SET | G22: =F22*D22 -> 0 | L22: 20 | M22: 44270 | N22: GREAT | O22: 2900000 | P22: LUNAS 29/7/21
A23: TDK ORDER | B23: DIFFUSER BRIO'18 | C23: HENDRIK | D23: 60 | E23: SET | G23: =F23*D23 -> 0
B24: SILT PLAT SAMPING BRIO'18 | C24: HENDRIK | D24: 10 | E24: SET | F24: 200000 | G24: =F24*D24 -> 2000000
B25: SILT PLAT SAMPING BRIO'18 LED | C25: HENDRIK | D25: 5 | E25: SET | F25: 300000 | G25: =F25*D25 -> 1500000 | O25: =SUM(O3:O24) -> 109948200
B26: HANDLE CRV'17 HITAM | C26: HENDRIK | D26: 3 | E26: SET | F26: 110000 | G26: =F26*D26 -> 330000
B27: OUTER CRV'17 HITAM | C27: HENDRIK | D27: 3 | E27: SET | F27: 125000 | G27: =F27*D27 -> 375000
B28: TANKI CRV'18 HITAM | C28: HENDRIK | D28: 3 | E28: SET | F28: 40000 | G28: =F28*D28 -> 120000
A29: 44259 | B29: SPOILER BRIO'18 PUTIH | C29: HENDRIK | D29: 3 | E29: SET | F29: 360000 | G29: =F29*D29 -> 1080000 | H29: =SUM(G29:G30) -> 3600000 | I29: LUNAS 5/3
B30: SPOILER BRIO'18 GRAY | C30: HENDRIK | D30: 7 | E30: SET | F30: 360000 | G30: =F30*D30 -> 2520000
A31: 44259 | B31: KARPET DASAR YARIS HITAM | C31: NVM | D31: 5 | E31: SET | F31: 180000 | G31: =F31*D31 -> 900000 | H31: =SUM(G31:G35) -> 3420000 | I31: JUNI | J31: GIRO 30/6/21
B32: KARPET DASAR AVANZA HITAM | C32: NVM | D32: 6 | E32: SET | F32: 180000 | G32: =F32*D32 -> 1080000
B33: KARPET DASAR XPANDER HITAM | C33: NVM | D33: 3 | E33: SET | F33: 180000 | G33: =F33*D33 -> 540000
B34: KARPET DASAR RUSH HITAM | C34: NVM | D34: 5 | E34: SET | F34: 180000 | G34: =F34*D34 -> 900000
B35: SARUNG STIR MB TECH HITAM MERAH | C35: NVM | D35: 1 | E35: SET | F35: 0 | G35: =F35*D35 -> 0
A36: 44260 | B36: TOWING ARB RUSH'18 MODEL FULL BODY KAKI PISAH | C36: ROYAL CITY | D36: 15 | E36: SET | F36: 400000 | G36: =F36*D36 -> 6000000 | H36: =SUM(G36) -> 6000000 | I36: JULI | J36: GIRO 30/7/21
A37: 44260 | B37: SARUNG JOK SATYA HITAM MERAH | C37: BUK IDA | D37: 2 | E37: SET | F37: 0 | G37: =F37*D37 -> 0
B38: SARUNG JOK GRAND INNOVA HITAM COKLAT | C38: BUK IDA | D38: 1 | E38: SET | F38: 0 | G38: =F38*D38 -> 0
A39: 44260 | B39: KARPET DASAR BRIO HITAM TIPIS | C39: HERMAN | D39: 25 | E39: SET | F39: 150000 | G39: =F39*D39 -> 3750000 | H39: =SUM(G39) -> 3750000 | I39: AGUSTUS
A40: 44261 | B40: FOOTSTEP (TANGGA)SAMPING INNOVA | C40: GREAT | D40: 5 | E40: SET | F40: 1450000 | G40: =F40*D40 -> 7250000 | H40: =SUM(G40) -> 7250000 | I40: JULI | J40: LUNAS TF29/7/21
...

Sheet APRIL
A1: BARANG MASUK ARAW FILM | L1: BON JATUH TEMPO AGUSTUS 2021 ( JT)
A2: TGL MASUK | B2: NAMA BARANG | C2: SUPLIER | D2: QTY | E2: SAT | F2: HARGA/PCS/SET | G2: JUMLAH | H2: TOTAL FAKTUR | I2: KET | L2: NO | M2: TGL BARANG MASUK | N2: NAMA SALES/ SUPLIER | O2: JUMLAH BON | P2: KET
A3: 44287 | B3: GPS GT 06N | C3: ASMIATI | D3: 6 | E3: SET | F3: 385000 | G3: =F3*D3 -> 2310000 | H3: =SUM(G3) -> 2310000 | I3: LUNAS | L3: 1 | M3: 44257 | N3: JSL | O3: 2400000 | P3: GIRO 15/8/21 | S3: 2400
A4: 44287 | B4: TOWING BAR MCC, TY FORTUNER 10-16/ INNOVA 12-16 | C4: NVM | D4: 4 | E4: SET | F4: 1250000 | G4: =F4*D4 -> 5000000 | H4: =G4 -> 5000000 | I4: AGUSTUS | J4: GIRO 30/8/21 | L4: 2 | M4: 44258 | N4: HERMAN | O4: 1710000 | P4: GIRO TGL 15/ TGL 30 | R4: =O4+O8+O9+O11+O12+O13+O15+O16+O17 -> 59030000 | S4: 4930
A5: 44288 | B5: GARNIS LAMPU DEPAN INNOVA'16 CHROME | C5: JSL | D5: 5 | E5: SET | F5: 110000 | G5: =F5*D5 -> 550000 | H5: =SUM(G5:G13) -> 6425000 | I5: SEPTEMBER | J5: GIRO 14/09/21 | L5: 3 | M5: 44258 | N5: JKI | O5: 2200000 | P5: LUNAS TF. TGL 25/8/21 | S5: 36626
B6: MIRROR COVER CHROME INNOVA'16/FORTUNER'16 | C6: JSL | D6: 5 | E6: SET | F6: 100000 | G6: =F6*D6 -> 500000 | L6: 4 | M6: 44259 | N6: HENDRIK | O6: 4225000 | P6: GIRO 17/8/21 | R6: =SUM(O5+O10) -> 3256000 | S6: 11700 | T6: =O4+O8+O9+O11+O12+O13+O15+O16+O17 -> 59030000
B7: GARNIS LAMPU DEPAN CALYA'19 CHROME | C7: JSL | D7: 5 | E7: SET | F7: 125000 | G7: =F7*D7 -> 625000 | L7: 5 | M7: 44259 | N7: HENDRIK | O7: 5820000
B8: GARNIS LAMPU BELAKANG CALYA'16 CHROME | C8: JSL | D8: 5 | E8: SET | F8: 110000 | G8: =F8*D8 -> 550000 | L8: 6 | M8: 44260 | N8: HERMAN | O8: 3750000 | P8: GIRO TGL 15/ TGL 30 | R8: =SUM(O6:O7) -> 10045000 | S8: =SUM(S3:S7) -> 55656
B9: GARNIS LAMPU DEPAN PAJERO '16 HITAM | C9: JSL | D9: 5 | E9: SET | F9: 110000 | G9: =F9*D9 -> 550000 | L9: 7 | M9: 44261 | N9: HERMAN | O9: 3750000 | P9: GIRO TGL 15/ TGL 30
B10: GARNIS LAMPU BELAKANG PAJERO'16 HITAM | C10: JSL | D10: 5 | E10: SET | F10: 125000 | G10: =F10*D10 -> 625000 | L10: 8 | M10: 44263 | N10: JKI | O10: 1056000 | P10: LUNAS TF. TGL 25/8/21
B11: OUTER CHROME INNOVA'16 | C11: JSL | D11: 10 | E11: SET | F11: 85000 | G11: =F11*D11 -> 850000 | L11: 9 | M11: 44263 | N11: HERMAN | O11: 2960000 | P11: GIRO TGL 15/ TGL 30 | R11: =O4+O8+O9+O11+O12+O13+O15+O16+O17 -> 59030000
B12: SILT PLATE SAMPING AVANZA/XENIA | C12: JSL | D12: 5 | E12: SET | F12: 35000 | G12: =F12*D12 -> 175000 | L12: 10 | M12: 44263 | N12: HERMAN | O12: 11630000 | P12: GIRO TGL 15/ TGL 30
B13: SILT PLATE BELAKANG BRIO'19 | C13: JSL | D13: 10 | E13: SET | F13: 200000 | G13: =F13*D13 -> 2000000 | L13: 11 | M13: 44264 | N13: HERMAN | O13: 9310000 | P13: GIRO TGL 15/ TGL 30 | R13: =O4+O8+O9+O11+O12 -> 23800000
A14: 44288 | B14: BESTCO(BODY COVER )XPANDER | C14: JSL | D14: 10 | E14: SET | F14: 118000 | G14: =F14*D14 -> 1180000 | H14: =SUM(G14) -> 1180000 | I14: SEPTEMBER | L14: 12 | M14: 44264 | N14: IRWAN | O14: 24960000 | P14: GIRO 30/8/21
A15: 44289 | B15: SARUNG JOK MB AGYA (MB 9001+9006) | C15: B'IDA | D15: 1 | E15: SET | F15: 0 | G15: =F15*D15 -> 0 | L15: 13 | M15: 44268 | N15: HERMAN | O15: 12060000 | P15: GIRO TGL 15/ TGL 30
A16: 44289 | B16: OUTER HITAM RUSH'18 | C16: JSL | D16: 10 | E16: SET | F16: 85000 | G16: =F16*D16 -> 850000 | H16: =SUM(G16:G18) -> 1825000 | I16: SEPTEMBER | J16: GIRO 14/09/21 | L16: 14 | M16: 44268 | N16: HERMAN | O16: 6970000 | P16: GIRO TGL 15/ TGL 30 | T16: =SUM(MARET!O21+MARET!O22) -> 10150000
B17: GARNIS LAMPU BELAKANG INNOVA'16 CHROME | C17: JSL | D17: 5 | E17: SET | F17: 125000 | G17: =F17*D17 -> 625000 | L17: 15 | M17: 44274 | N17: HERMAN | O17: 6890000 | P17: GIRO TGL 15/ TGL 30
B18: TANKI RUSH '18 HITAM | C18: JSL | D18: 10 | E18: SET | F18: 35000 | G18: =F18*D18 -> 350000 | L18: 16 | M18: 44274 | N18: MOBILINDO | O18: 4010000 | P18: GIRO 30/8/21
A19: 44289 | B19: TV ANDROID ENIGMA 10" | C19: MOBILINDO | D19: 5 | E19: SET | F19: 2000000 | G19: =F19*D19 -> 10000000 | H19: =SUM(G19) -> 10000000 | I19: SEPTEMBER | J19: GIRO 20/9/21 | L19: 17 | M19: 44287 | N19: NVM | O19: 5000000 | P19: GIRO 30/8/21
A20: 44294 | B20: KARPET KARET 3D HITAM | C20: HERMAN | D20: 12 | E20: SET | F20: 175000 | G20: =F20*D20 -> 2100000 | H20: =SUM(G20) -> 2100000 | I20: SEPTEMBER | J20: GIRO 30/9/21 | L20: 18 | M20: 44301 | N20: TJM | O20: 6350000 | R20: =SUM(O19+O20) -> 11350000
A21: 44295 | B21: FRONT GUARD(PLANG DEPAN)RHINO GUARD PAJERO'19 | C21: TJM | D21: 1 | E21: SET | F21: 2150000 | G21: =F21*D21 -> 2150000 | H21: =SUM(G21:G22) -> 4300000 | I21: JULI | J21: LUNAS TF 28/7/21 | L21: 19 | M21: 44312 | N21: HENDRIK | O21: 2550000 | P21: GIRO TGL 30/8/21
B22: FRONT GUARD(PLANG DEPAN)RHINO GUARD FORTUNER'16 | C22: TJM | D22: 1 | E22: SET | F22: 2150000 | G22: =F22*D22 -> 2150000 | L22: 20 | M22: 44366 | N22: OTOPROJECT | O22: 5790000 | P22: LUNAS TF. TGL 12/8/21
A23: 44296 | B23: AN INNOVA 16 SIDE WINDOW TRIM CHROME 8PCS | C23: JSL | D23: 5 | E23: SET | F23: 150000 | G23: =F23*D23 -> 750000 | H23: =SUM(G23:G26) -> 3425000 | I23: SEPTEMBER | J23: GIRO 14/09/21 | L23: 21 | M23: 44410 | N23: JAYA MADANI | O23: 3600000 | P23: LUNAS TF. TGL 14/8/21
B24: AN INNOVA 16 SIDE BODY MOLDING CHROME | C24: JSL | D24: 5 | E24: SET | F24: 300000 | G24: =F24*D24 -> 1500000 | L24: 22 | M24: 44398 | N24: BAN PEMKO PARIAMAN | O24: 4450000 | P24: GIRO TGL 25/8/21
B25: CALYA 19/ SIGRA 19 HEAD LAMP GARNISH BLACKTIVO | C25: JSL | D25: 5 | E25: SET | F25: 125000 | G25: =F25*D25 -> 625000 | L25: 23 | M25: 44302 | N25: MR BOSS | O25: 1230000 | P25: GIRO TGL 30/8/21 | R25: =O25+O26 -> 2190000
B26: CALYA 16/SIGRA 16 TAIL LAMP GARNISH BLACTIVO | C26: JSL | D26: 5 | E26: SET | F26: 110000 | G26: =F26*D26 -> 550000 | L26: 24 | M26: 44316 | N26: MR BOSS | O26: 960000 | P26: GIRO TGL 30/8/22
A27: 44296 | B27: KACAFILM WINTERBLAS HCD 10G C 70 (2101080049KA2E) | C27: WINCOS | D27: 1 | E27: ROL | F27: 0 | G27: =F27*D27 -> 0 | I27: BRIO | L27: 25 | M27: 44261 | N27: MR.BOSS | O27: 1500000 | P27: GIRO 30/7/21
B28: KACAFILM WINTERBLAS HCD 10G C 70 (2101080052KA28) | C28: WINCOS | D28: 1 | E28: ROL | F28: 0 | G28: =F28*D28 -> 0 | I28: BRIO | L28: 26 | M28: 44415 | N28: WINCOS | O28: 39600000 | P28: LUNAS TGL 30/8/21
B29: KACAFILM WINTERBLAS HCD 30G C 70 (2004240080EGAH) | C29: WINCOS | D29: 1 | E29: ROL | F29: 0 | G29: =F29*D29 -> 0 | I29: BRIO
A30: 44298 | B30: SARUNG JOK GRAND INNOVA G mb 9001 BD + 9012 BD | C30: BUK IDA | D30: 1 | E30: SET | F30: 0 | G30: =F30*D30 -> 0 | N30: TOTAL | O30: =SUM(O3:O29) -> 174731000
B31: SARUNG JOK XPANDER mb 9001 + 9015 | C31: BUK IDA | D31: 1 | E31: SET | F31: 0 | G31: =F31*D31 -> 0
A32: 44299 | B32: SPOILER BRIO'18 BLACK | C32: HENDRIK | D32: 5 | E32: SET | F32: 375000 | G32: =F32*D32 -> 1875000 | H32: =SUM(G32:G33) -> 3750000 | I32: LUNAS 13 APRIL 2021 | N32: LUNAS TRANSFER | O32: =O5+O10+O22+O23+O28 -> 52246000
B33: SPOILER BRIO'18 RED | C33: HENDRIK | D33: 5 | E33: SET | F33: 375000 | G33: =F33*D33 -> 1875000
A34: 44301 | B34: LEM 3M | C34: LEO | D34: 50 | E34: SET | F34: 37500 | G34: =F34*D34 -> 1875000 | H34: =SUM(G34) -> 1875000 | I34: SEPTEMBER | N34: DI BYR DENGAN GIRO | O34: =O3+O4+O6+O7+O8+O9+O11+O12+O13+O14+O15+O16+O17+O18+O19+O20+O21+O24+O25+O26+O27 -> 122485000
A35: 44301 | B35: KARPET DASAR PAJERO'16 HITAM | C35: TJM | D35: 10 | E35: SET | F35: 180000 | G35: =F35*D35 -> 1800000 | H35: =SUM(G35:G40) -> 6350000 | I35: AGUSTUS | J35: GIRO 30/8/21
B36: KARPET DASAR XPANDER HITAM | C36: TJM | D36: 10 | E36: SET | F36: 185000 | G36: =F36*D36 -> 1850000
B37: KARPET DASAR FORTUNER HITAM | C37: TJM | D37: 5 | E37: SET | F37: 180000 | G37: =F37*D37 -> 900000
B38: KARPET DASAR BRIO'18 HITAM | C38: TJM | D38: 5 | E38: SET | F38: 180000 | G38: =F38*D38 -> 900000
B39: KARPET DASAR INNOVA'16 HITAM | C39: TJM | D39: 5 | E39: SET | F39: 180000 | G39: =F39*D39 -> 900000
B40: SARUNG STIR MBTECH | C40: TJM | D40: 4 | E40: SET | G40: =F40*D40 -> 0
...

Sheet MEI
A1: BARANG MASUK ARAW FILM
A2: TGL MASUK | B2: NAMA BARANG | C2: SUPLIER | D2: QTY | E2: SAT | F2: HARGA/PCS/SET | G2: JUMLAH | H2: TOTAL FAKTUR | I2: KET | L2: BON JATUH TEMPO SEPTEMBER 2021 ( JT)
A3: 44317 | B3: KLAKSON ORCA | C3: ORCA | D3: 100 | E3: SET | F3: 80000 | G3: =F3*D3 -> 8000000 | H3: =SUM(G3) -> 8000000 | I3: OKTOBER | L3: NO | M3: TGL BARANG MASUK | N3: NAMA SALES/ SUPLIER | O3: JUMLAH BON | P3: KET
A4: 44317 | B4: LOGO RS | C4: HERMAN | D4: 50 | E4: SET | F4: 30000 | G4: =F4*D4 -> 1500000 | H4: =SUM(G4) -> 1500000 | I4: GIRO 30/10/21 | L4: 1 | M4: 44278 | N4: IRWAN | O4: 700000 | P4: GIRO 30/9/2021 | Q4: V
A5: 44319 | B5: KD CALYA HITAM | C5: TJM | D5: 10 | E5: SET | F5: 180000 | G5: =F5*D5 -> 1800000 | H5: =SUM(G5) -> 1800000 | I5: SEPTEMBER | L5: 2 | M5: 44274 | N5: MOBILINDO | O5: 7890000 | P5: GIRO 20/9/21 | Q5: V
A6: 44319 | B6: SARUNG JOK AGYA (MB 9001 +MB 9007) | C6: B'IDA | D6: 1 | E6: SET | F6: 0 | G6: 0 | L6: 3 | M6: 44274 | N6: MOBILINDO | O6: 10335000 | P6: GIRO 20/9/21 | Q6: V
A7: 44319 | B7: BESTCO CAR COVER FORTUNER | C7: JSL | D7: 5 | E7: SET | F7: 142000 | G7: =F7*D7 -> 710000 | H7: =SUM(G7:G11) -> 5695000 | I7: OKTOBER | J7: GIRO 14/10/21 | L7: 4 | M7: 44274 | N7: HERMAN | O7: 6560000 | P7: GIRO 10/9/21 | Q7: V
B8: BESTCO CAR COVER BRIO'18 | C8: JSL | D8: 20 | E8: SET | F8: 105000 | G8: =F8*D8 -> 2100000 | L8: 5 | M8: 44281 | N8: MOBILINDO | O8: 2250000 | P8: GIRO 20/9/21 | Q8: V
B9: BESTCO CAR COVER BRIO | C9: JSL | D9: 12 | E9: SET | F9: 105000 | G9: =F9*D9 -> 1260000 | L9: 6 | M9: 44284 | N9: HERMAN | O9: 0 | P9: DIKEMBALIKAN
B10: BESTCO CAR COVER YARIS | C10: JSL | D10: 5 | E10: SET | F10: 105000 | G10: =F10*D10 -> 525000 | L10: 7 | M10: 44288 | N10: JSL | O10: 6425000 | P10: GIRO 14/09/21 | Q10: V
B11: BESTCO CAR COVER CALYA/SIGRA | C11: JSL | D11: 10 | E11: SET | F11: 110000 | G11: =F11*D11 -> 1100000 | L11: 8 | M11: 44288 | N11: JSL | O11: 1180000
A12: 44319 | B12: GRILL PAJERO MDL ALPARD (DIKEMBALIKAN) | C12: IRWAN | D12: 1 | E12: SET | F12: 1250000 | G12: =F12*D12 -> 1250000 | H12: =SUM(G12:G18) -> 20950000 | I12: OKTOBER | J12: GIRO 30/10/21 | L12: 9 | M12: 44289 | N12: JSL | O12: 1825000
B13: GRILL RUSH'18 MDL PRADO | C13: IRWAN | D13: 2 | E13: SET | F13: 700000 | G13: =F13*D13 -> 1400000 | L13: 10 | M13: 44289 | N13: MOBILINDO | O13: 10000000 | P13: GIRO 20/9/21 | Q13: V
B14: GRILL INNOVA'16 MDL ALPARD | C14: IRWAN | D14: 1 | E14: SET | F14: 1500000 | G14: =F14*D14 -> 1500000 | L14: 11 | M14: 44294 | N14: HERMAN | O14: 2100000 | P14: GIRO TGL 30/9/21 | Q14: V
B15: DOUBLE TIPE TRANSPARAN | C15: IRWAN | D15: 150 | E15: SET | F15: 40000 | G15: =F15*D15 -> 6000000 | L15: 12 | M15: 44296 | N15: JSL | O15: 3425000 | P15: GIRO 14/09/21 | Q15: V
C16: IRWAN | D16: 12 | E16: SET | F16: 300000 | G16: =F16*D16 -> 3600000 | L16: 13 | M16: 44301 | N16: LEO | O16: 1875000 | P16: GIRO TGL 15/9/21 | Q16: V
B17: FOGLAMP ALL NEW AVZ RUSH '18 | C17: IRWAN | D17: 5 | E17: SET | F17: 450000 | G17: =F17*D17 -> 2250000 | L17: 14 | M17: 44303 | N17: JSL | O17: 5125000 | P17: GIRO 14/9/21 | Q17: V
B18: KAKI SPORT RACK | C18: IRWAN | D18: 11 | E18: SET | F18: 450000 | G18: =F18*D18 -> 4950000 | L18: 15 | M18: 44308 | N18: JSL | O18: 1890000
A19: 44319 | B19: SILICON KUNCI HONDA BRIO HITAM | C19: HERMAN | D19: 10 | E19: SET | F19: 15000 | G19: =F19*D19 -> 150000 | H19: =SUM(G19:G30) -> 2875000 | I19: GIRO 30/10/21 | L19: 16 | M19: 44308 | N19: HENDRIK | O19: 6950000 | P19: GIRO TGL 20/09/21 | Q19: V
B20: SILICON KUNCI HONDA BRIO MERAH | C20: HERMAN | D20: 5 | E20: SET | F20: 15000 | G20: =F20*D20 -> 75000 | L20: 17 | M20: 44351 | N20: HENDRIK | O20: 1500000
B21: SILICON KUNCI HONDA BRIO BIRU | C21: HERMAN | D21: 5 | E21: SET | F21: 15000 | G21: =F21*D21 -> 75000 | L21: 18 | M21: 44309 | N21: HERMAN | O21: 8835000 | P21: GIRO TGL 30/9/21 | Q21: V
B22: SILICON KUNCI HONDA INNOVA HITAM | C22: HERMAN | D22: 10 | E22: SET | F22: 15000 | G22: =F22*D22 -> 150000 | L22: 19 | M22: 44310 | N22: AM77 | O22: 3600000 | P22: GIRO 30/9/21 | Q22: V
B23: SILICON KUNCI HONDA INNOVA MERAH | C23: HERMAN | D23: 5 | E23: SET | F23: 15000 | G23: =F23*D23 -> 75000 | L23: 20 | M23: 44319 | N23: TJM | O23: 1800000 | P23: GIRO 30/9/21 | Q23: V
B24: SILICON KUNCI HONDA INNOVA BIRU | C24: HERMAN | D24: 5 | E24: SET | F24: 15000 | G24: =F24*D24 -> 75000 | L24: 21 | M24: 44362 | N24: MR. BOSS | O24: 2700000 | P24: GIRO TGL 30/9/21 | Q24: V
B25: SILICON KUNCI HONDA RUSH/VELOZ BIRU | C25: HERMAN | D25: 5 | E25: SET | F25: 15000 | G25: =F25*D25 -> 75000 | L25: 23 | M25: 44313 | N25: JKI | O25: 2200000 | P25: GIRO TGL 30/9/21 | Q25: V
B26: SILICON KUNCI CALYA HITAM | C26: HERMAN | D26: 10 | E26: SET | F26: 15000 | G26: =F26*D26 -> 150000 | L26: 24 | M26: 44396 | N26: OTOPROJECT | O26: 10305000 | P26: LUNAS TF. 22/9/21
B27: SILICON KUNCI CALYA MERAH | C27: HERMAN | D27: 5 | E27: SET | F27: 15000 | G27: =F27*D27 -> 75000 | L27: 25 | M27: 44404 | N27: OTOPROJECT | O27: 2975000
B28: SILICON KUNCI CALYA BIRU | C28: HERMAN | D28: 5 | E28: SET | F28: 15000 | G28: =F28*D28 -> 75000 | L28: 26 | M28: 44442 | N28: WINCOS | O28: 19800000 | P28: LUNAS TF 29/9/21
B29: EMBLEM CUP MESIN PAJERO SPORT'16 CHROME | C29: HERMAN | D29: 10 | E29: SET | F29: 95000 | G29: =F29*D29 -> 950000 | L29: 27 | M29: 44434 | N29: JAYA MADANI | O29: 3600000 | P29: LUNAS TF. 20/9/21
B30: EMBLEM CUP MESIN PAJERO SPORT'16 HITAM | C30: HERMAN | D30: 10 | E30: SET | F30: 95000 | G30: =F30*D30 -> 950000
A31: 44319 | B31: KACA FILM WINTERBLAST HCD 30G C 70 (2101080254K2AC) | C31: WINCOS | D31: 1 | E31: ROLL | F31: 0 | G31: =F31*D31 -> 0 | H31: BRIO | I31: BRIO | N31: TOTAL | O31: =SUM(O4:O30) -> 125845000
A32: 44322 | B32: SPOILER BRIO'18 WHITE | C32: HENDRIK | D32: 3 | E32: SET | F32: 375000 | G32: =F32*D32 -> 1125000 | H32: =SUM(G32:G35) -> 3750000 | I32: LUNAS TF. 18/5/21
B33: SPOILER BRIO'18 MODREN STEEL | C33: HENDRIK | D33: 3 | E33: SET | F33: 375000 | G33: =F33*D33 -> 1125000 | N33: BYR DG GIRO | O33: =O25+O24+O23+O21+O20+O19+O17+O16+O15+O14+O13+O12+O11+O10+O8+O7+O6+O5+O4+O18+O22 -> 89165000
B34: SPOILER BRIO'18 RED | C34: HENDRIK | D34: 2 | E34: SET | F34: 375000 | G34: =F34*D34 -> 750000 | N34: GIRO 50 JT AWAL | O34: =O5+O6+O7+O8+O10+O11+O12+O15+O16+O17+O18 -> 48780000 | P34: V
B35: SPOILER BRIO'18 YELLOW | C35: HENDRIK | D35: 2 | E35: SET | F35: 375000 | G35: =F35*D35 -> 750000 | N35: GIRO 30 JT AKHIR | O35: =O4+O13+O14+O19+O20+O21 -> 30085000 | P35: V
A36: 44327 | B36: KACA FILM WINTERBLAST HCD 30G C 70 (2102150119K2AB) | C36: WINCOS | D36: 1 | E36: ROLL | F36: 0 | G36: 0 | H36: 0 | I36: BRIO | N36: GIRO 8.5 JT | O36: =O22+O23+O24+O25 -> 10300000 | P36: V
A37: 44335 | B37: GRILL COVER BRIO 18 BLACK | C37: JSL | D37: 1 | E37: PCS | F37: 550000 | G37: =SUM(F37*D37) -> 550000 | H37: =SUM(G37:G40) -> 2200000 | I37: OKTOBER | N37: LUNAS TRANSFER | O37: =O29+O27+O26+O28 -> 36680000
B38: GRILL COVER BRIO 18 BLACKTIVO | C38: JSL | D38: 1 | E38: PCS | F38: 550000 | G38: =SUM(F38*D38) -> 550000
B39: GRILL COVER BRIO 18 SILVER KOMB | C39: JSL | D39: 1 | E39: PCS | F39: 550000 | G39: =SUM(F39*D39) -> 550000
B40: GRILL COVER BRIO 18 TAFFETA WHITE | C40: JSL | D40: 1 | E40: PCS | F40: 550000 | G40: =SUM(F40*D40) -> 550000
...

Sheet JUNI
A1: BARANG MASUK ARAW FILM | K1: BON JATUH TEMPO OKTOBER 2021 ( JT)
A2: TGL MASUK | B2: NAMA BARANG | C2: SUPLIER | D2: QTY | E2: SAT | F2: HARGA/PCS/SET | G2: JUMLAH | H2: TOTAL FAKTUR | I2: KET | K2: NO | L2: TGL BARANG MASUK | M2: NAMA SALES/ SUPLIER | N2: JUMLAH BON | O2: KET | P2: CEK
A3: 44348 | B3: SPOILER A.N BRIO HITAM | C3: KO AKHON | D3: 3 | E3: PCS | F3: 400000 | G3: =SUM(F3*D3) -> 1200000 | H3: =SUM(G3:G8) -> 11600000 | I3: NOVEMBER (PERTENGAHAN) | K3: 1 | L3: 44305 | M3: JKI | N3: 7700000 | O3: GIRO TGL 30/10/21
B4: SPOILER A.N BRIO MERAH | C4: KO AKHON | D4: 5 | E4: PCS | F4: 400000 | G4: =SUM(F4*D5) -> 2000000 | K4: 2 | L4: 44309 | M4: YUSUF ORCA | N4: 1120000 | O4: GIRO TF. TGL 30/10/21
B5: SPOILER A.N BRIO KUNING | C5: KO AKHON | D5: 5 | E5: PCS | F5: 400000 | G5: =SUM(F5*D6) -> 2000000 | K5: 3 | L5: 44310 | M5: HERMAN | N5: 1500000 | O5: GIRO TGL 30/10/21 | P5: V
B6: SPOILER A.N BRIO GREY | C6: KO AKHON | D6: 5 | E6: PCS | F6: 400000 | G6: =SUM(F6*D6) -> 2000000 | K6: 4 | L6: 44313 | M6: AM77 | N6: 4200000 | O6: GIRO 30/10/21
B7: SPOILER A.N BRIO PUTIH | C7: KO AKHON | D7: 6 | E7: PCS | F7: 400000 | G7: =SUM(F7*D7) -> 2400000 | K7: 5 | L7: 44315 | M7: IRWAN | N7: 22160000 | O7: GIRO 30/10/21
B8: SPOILER A.N BRIO SILVER | C8: KO AKHON | D8: 5 | E8: PCS | F8: 400000 | G8: =SUM(F8*D8) -> 2000000 | K8: 6 | L8: 44317 | M8: HERMAN | N8: 1500000 | O8: GIRO TGL 30/10/21 | P8: V | Q8: =N5+N8+N14 -> 5875000
A9: 44348 | B9: TOW BEL CUSTOM W/L + ANTING -PAJERO SPORT DUDUKAN MERAH FB | C9: AM77 | D9: 2 | E9: SET | F9: 2200000 | G9: =SUM(F9*D9) -> 4400000 | H9: =SUM(G9) -> 4400000 | I9: GIRO OKTOBER | K9: 7 | L9: 44317 | M9: ORCA | N9: 8000000 | O9: GIRO TF. TGL 30/10/21 | Q9: =5000000+Q8 -> 10875000
A10: 44348 | B10: ROOF BOX KANAKA (BC) HITAM | C10: AM77 | D10: 1 | E10: PCS | F10: 3700000 | G10: =SUM(F10*D10) -> 3700000 | H10: =SUM(G10) -> 3700000 | K10: 8 | L10: 44316 | M10: ORCA | N10: 7500000
A11: 44348 | B11: KARPET MIE 3RAY HITAM /MERAH | C11: KO AKHON | D11: 5 | E11: ROL | F11: 525000 | G11: =SUM(F11*D11) -> 2625000 | H11: =SUM(G11:G12) -> 4725000 | I11: NOVEMBER (PERTENGAHAN) | K11: 9 | L11: 44316 | M11: ORCA | N11: 365000
B12: KARPET MIE 3 RAY COKLAT/CREAM | C12: KO AKHON | D12: 4 | E12: ROL | F12: 525000 | G12: =SUM(F12*D12) -> 2100000 | K12: 10 | L12: 44319 | M12: JSL | N12: 5695000 | O12: GIRO 14/10/21 | P12: V
A13: 44350 | B13: KARPET DASAR BRIO TIPIS | C13: HERMAN | D13: 50 | E13: SET | F13: 150000 | G13: =F13*D13 -> 7500000 | H13: =SUM(G13) -> 7500000 | I13: GIRO 10/11/21 | K13: 11 | L13: 44319 | M13: IRWAN | N13: 20950000 | O13: GIRO 30/10/21
A14: 44350 | B14: KACA FILM AG 80% | C14: JKI | D14: 3 | E14: SET | F14: 1100000 | G14: =F14*D14 -> 3300000 | H14: =SUM(G14) -> 3300000 | I14: NOVEMBER | K14: 12 | L14: 44319 | M14: HERMAN | N14: 2875000 | O14: GIRO TGL 30/10/21
A15: 44351 | B15: TALANG AIR CITY HB | C15: HENDRIK | D15: 10 | E15: SET | F15: 150000 | G15: =SUM(F15*D15) -> 1500000 | H15: =SUM(G15) -> 1500000 | I15: OKTOBER | K15: 13 | L15: 44335 | M15: JSL | N15: 2200000 | O15: GIRO TGL 10/10/21 | P15: V | Q15: =SUM(N15:N17) -> 4800000
A16: 44352 | B16: REFLEKTOR BUMPER HRV | C16: KO AKHON | D16: 3 | E16: SET | F16: 325000 | G16: =SUM(F16*D16) -> 975000 | H16: =SUM(G16) -> 975000 | I16: NOVEMBER | K16: 14 | L16: 44343 | M16: JSL | N16: 1100000 | P16: V
A17: 44352 | B17: KACA FILM CPF1 60% | C17: JKI | D17: 1 | E17: ROL | F17: 5500000 | G17: =SUM(F17*D17) -> 5500000 | H17: =SUM(G17) -> 5500000 | I17: NOVEMBER | K17: 15 | L17: 44343 | M17: JSL | N17: 1500000 | P17: V
A18: 44354 | B18: TANGGA SAMPING INNOVA | C18: IRWAN | D18: 5 | E18: SET | F18: 1550000 | G18: =SUM(F18*D18) -> 7750000 | H18: =SUM(G18:G19) -> 15500000 | I18: NOVEMBER (5.500.000) | K18: 16 | L18: 44354 | M18: NVM | N18: 7040000 | O18: GIRO TGL 30/10/21 | P18: V
B19: TANGGA SAMPING INNOVA | C19: IRWAN | D19: 5 | E19: SET | F19: 1550000 | G19: =SUM(F19*D19) -> 7750000 | I19: DESEMBER (10.000.000) | K19: 17 | L19: 44361 | M19: TJM | N19: 7400000 | P19: V
A20: 44354 | B20: RETRAC MIRROR INNOVA | C20: LEO | D20: 2 | E20: SET | F20: 1000000 | G20: =SUM(F20*D20) -> 2000000 | H20: =SUM(G20) -> 2000000 | I20: NOVEMBER | K20: 18 | L20: 44424 | M20: OTOPROJECT | N20: 10656000 | O20: GIRO TGL 25/10/21 | P20: V
A21: 44354 | B21: TOWING MCC FORTUNER TRD | C21: GREAT(KO AKHON) | D21: 5 | E21: SET | F21: 1200000 | G21: =SUM(F21*D21) -> 6000000 | H21: =SUM(G21:G22) -> 12000000 | I21: NOVEMBER | K21: 19 | L21: 44347 | M21: AM77 | N21: 3700000 | O21: GIRO TGL 15/10/21 | P21: V
B22: TOWING MCC INNOVA REBRON | C22: GREAT | D22: 5 | E22: SET | F22: 1200000 | G22: =SUM(F22*D22) -> 6000000 | K22: 20 | L22: 44348 | M22: AM77 | N22: 4400000 | P22: V | Q22: PNDAHAN DARI GIRO NOVEMBER
A23: 44354 | B23: KARPET UNIVERSAL BLACK | C23: NVM | D23: 10 | E23: SET | F23: 145000 | G23: =SUM(F23*D23) -> 1450000 | H23: =SUM(G23:G42) -> 3640000 | I23: GIRO OKTOBER | J23: =SUM(H23:H44) -> 7040000 | K23: 21 | L23: 44348 | M23: AM77 | N23: 3700000 | P23: V
B24: SARUNG STIR OMAX BLACK/RED | C24: NVM | D24: 3 | E24: SET | F24: 125000 | G24: =SUM(F24*D24) -> 375000 | K24: 22 | L24: 44403 | M24: HERMAN | N24: 5000000 | O24: GIRO TGL 30/10/21
B25: CAMERA BLK CAMERA (INFRA RED) | C25: NVM | D25: 9 | E25: SET | F25: 165000 | G25: =SUM(F25*D25) -> 1485000
B26: KANCING BUMPER SPOILER/FENDER (100 PCS) | C26: NVM | D26: 1 | E26: PACK | F26: 90000 | G26: =SUM(F26*D26) -> 90000 | N26: =SUM(N3:N25) -> 130261000
B27: LAP MICROFIBER RAZO,ALL PURPOSE ,GREEEN | C27: NVM | D27: 1 | E27: SET | F27: 15000 | G27: =SUM(F27*D27) -> 15000
B28: LAP MICROFIBER RAZO,ALL PURPOSE ,PINK | C28: NVM | D28: 1 | E28: SET | F28: 15000 | G28: =SUM(F28*D28) -> 15000
B29: LAP MICROFIBER RAZO,ALL PURPOSE ,WHITE | C29: NVM | D29: 1 | E29: SET | F29: 15000 | G29: =SUM(F29*D29) -> 15000 | K29: 0 | M29: GIRO 20 JT | N29: =N15+N16+N17+N21+N22+N23+N12 -> 22295000
B30: LAP MICROFIBER RAZO,ALL PURPOSE ,PURPLE | C30: NVM | D30: 1 | E30: SET | F30: 15000 | G30: =SUM(F30*D30) -> 15000 | K30: 0 | M30: GIRO 30 JT | N30: =N20+N19+N18+N8+N5 -> 28096000
B31: LAP MICROFIBER RAZO,ALL PURPOSE ,YELLOW | C31: NVM | D31: 1 | E31: SET | F31: 15000 | G31: =SUM(F31*D31) -> 15000 | M31: GIRO 80.270 JT | N31: =N24+N13+N11+N10+N9+N7+N6+N4+N3+N14 -> 79870000
B32: LAP MICROFIBER RAZO,ALL PURPOSE ,RED(GRS) | C32: NVM | D32: 1 | E32: SET | F32: 15000 | G32: =SUM(F32*D32) -> 15000
B33: LAP MICROFIBER RAZO,ALL PURPOSE ,(GRS) WHITE | C33: NVM | D33: 1 | E33: SET | F33: 15000 | G33: =SUM(F33*D33) -> 15000 | J33: =SUM(H23+H43+H49) -> 14440000 | N33: =SUM(N29:N32) -> 130261000
B34: LAP MICROFIBER RAZO,ALL PURPOSE ,(GRS) YELLOW | C34: NVM | D34: 1 | E34: SET | F34: 15000 | G34: =SUM(F34*D34) -> 15000
B35: LAP MICROFIBER RAZO,ALL PURPOSE ,GREY | C35: NVM | D35: 1 | E35: SET | F35: 15000 | G35: =SUM(F35*D35) -> 15000
B36: LAP MICROFIBER RAZO,ALL PURPOSE ,PURPLE | C36: NVM | D36: 1 | E36: SET | F36: 15000 | G36: =SUM(F36*D36) -> 15000
B37: LAP MICROFIBER RAZO,ALL PURPOSE ,WHITE | C37: NVM | D37: 1 | E37: SET | F37: 15000 | G37: =SUM(F37*D37) -> 15000
B38: LAP MICROFIBER RAZO,ALL PURPOSE ,BLUE | C38: NVM | D38: 1 | E38: SET | F38: 15000 | G38: =SUM(F38*D38) -> 15000
B39: LAP MICROFIBER RAZO,ALL PURPOSE ,GREY | C39: NVM | D39: 1 | E39: SET | F39: 15000 | G39: =SUM(F39*D39) -> 15000
B40: LAP MICROFIBER RAZO,ALL PURPOSE ,PURPLE | C40: NVM | D40: 1 | E40: SET | F40: 15000 | G40: =SUM(F40*D40) -> 15000
...

Sheet JULI
A1: BARANG MASUK ARAW FILM | K1: BON JATUH TEMPO NOVEMBER 2021 ( JT)
A2: TGL MASUK | B2: NAMA BARANG | C2: SUPLIER | D2: QTY | E2: SAT | F2: HARGA/PCS/SET | G2: JUMLAH | H2: TOTAL FAKTUR | I2: KET | K2: NO | L2: TGL BARANG MASUK | M2: NAMA SALES/ SUPLIER | N2: JUMLAH BON | O2: KET
A3: 44378 | B3: TOWBEL CUSTOM W/L + ANTING- PAJERO SPORT DUDUKAN MERAH FB | C3: AM77 | D3: 2 | E3: SET | F3: 2200000 | G3: =SUM(F3*D3) -> 4400000 | H3: =SUM(G3) -> 4400000 | I3: DESEMBER GIRO | K3: 1 | L3: 44343 | M3: KO AKHON | N3: 9600000 | O3: LUNAS TF. TGL 15/10/21
A4: 44379 | B4: SARUNG JOK BRIO SATYA MB TECK (9001+9005) | C4: BUK IDA | D4: 1 | E4: SET | F4: 0 | G4: =SUM(F4*D4) -> 0 | H4: 0 | K4: 2 | L4: 44344 | M4: HERMAN | N4: 940000 | O4: GIRO TGL 10/11/21 | R4: PINDAH KE BULAN 10 (5JT) | T4: V
A5: 44380 | B5: KACA FILM WINTERBLAST HCD 10G C 70 (2103150087K2AG) | C5: WINCOWS | D5: 1 | E5: ROL | F5: 0 | G5: 0 | H5: 0 | I5: BRIO | K5: 3 | L5: 44344 | M5: IRWAN | N5: 15782000 | O5: GIRO 15/11/21 | Q5: =N5+N6 -> 17577000 | R5: V
B6: KACA FILM WINTERBLAST HCD 10G C 70 (2103150085K2AE) | C6: WINCOWS | D6: 1 | E6: ROL | F6: 0 | G6: 0 | K6: 4 | L6: 44344 | M6: IRWAN | N6: 1795000
B7: KACA FILM WINTERBLAST HCD 30G C 70 (2103120127K2A8) | C7: WINCOWS | D7: 1 | E7: ROL | F7: 0 | G7: 0 | K7: 5 | L7: 44345 | M7: LEO | N7: 3900000 | O7: GIRO TGL 15/11/21 | Q7: V | R7: =N4+N13+N21 -> 17040000
A8: 44382 | B8: SARUNG JOK RAIZE MB TECK (9001+9016) | C8: TOLIB | D8: 1 | E8: SET | F8: 1550000 | G8: =SUM(F8*D8) -> 1550000 | H8: =SUM(G8) -> 1550000 | I8: SISA 550.000 | K8: 6 | L8: 44366 | M8: AM77 | N8: 5920000 | O8: GIRO TGL.15/11/21
A9: 44382 | B9: ROOF RACK ADVENTURE | C9: PEGASUS | D9: 1 | E9: SET | F9: 1000000 | G9: =SUM(F9*D9) -> 1000000 | H9: =SUM(G9:G11) -> 5900000 | I9: LUNAS | K9: 7 | L9: 44348 | M9: KO AKHON | N9: 11600000 | O9: LUNAS TF. TGL 15/10/21 | Q9: =N3+N9+N11+N15+N18+N19+N20 -> 46200000 | R9: 17040000
B10: MIGHTY SPORT RACK | C10: PEGASUS | D10: 1 | E10: SET | F10: 1100000 | G10: =SUM(F10*D10) -> 1100000 | K10: 8 | L10: 44369 | M10: AM77 | N10: 6260000 | O10: GIRO TGL.15/11/21 | R10: =R7-R9 -> 0
B11: PAJERO 2021 BUMPER RHINO GUARD II | C11: PEGASUS | D11: 2 | E11: SET | F11: 1900000 | G11: =SUM(F11*D11) -> 3800000 | K11: 9 | L11: 44348 | M11: KO AKHON | N11: 4725000 | O11: LUNAS TF. TGL 15/10/21
A12: 44383 | B12: SARUNG JOK SIGRA/LEXUS HITAM CAPUCINO (VARIASI) | C12: AM77 | D12: 1 | E12: SET | F12: 740000 | G12: =SUM(F12*D12) -> 740000 | H12: =SUM(G12:G16) -> 5720000 | I12: DESEMBER GIRO | K12: 10 | L12: 44350 | M12: JKI | N12: 3300000 | O12: GIRO TGL 30/11/21 | R12: =N3+N9+N11 -> 25925000
B13: SARUNG JOK RUSH '18/LEXUS HITAM ABU | C13: AM77 | D13: 1 | E13: SET | F13: 740000 | G13: =SUM(F13*D13) -> 740000 | K13: 11 | L13: 44350 | M13: HERMAN | N13: 7500000 | O13: GIRO TGL 10/11/21
B14: SARUNG JOK BRIO E/ LEXUS HITAM CAPPUCINO | C14: AM77 | D14: 2 | E14: SET | F14: 640000 | G14: =SUM(F14*D14) -> 1280000 | K14: 12 | L14: 44352 | M14: JKI | N14: 5500000 | O14: GIRO TGL 30/11/21
B15: SARUNG JOK AVANZA'15/LEXUS HITAM CAPPUCINO | C15: AM77 | D15: 2 | E15: SET | F15: 740000 | G15: =SUM(F15*D15) -> 1480000 | K15: 13 | L15: 44352 | M15: KO AKHON | N15: 975000 | O15: LUNAS TF. TGL 29/10/21 | R15: =R12+R16 -> 46200000
B16: SARUNG JOK AVANZA'15/LEXUS HITAM | C16: AM77 | D16: 2 | E16: SET | F16: 740000 | G16: =SUM(F16*D16) -> 1480000 | K16: 14 | L16: 44354 | M16: IRWAN | N16: 5500000 | O16: GIRO TGL 30/11/21 | R16: =N15+N18+N19+N20 -> 20275000
A17: 44385 | B17: SARUNG STIR DRD HITAM-MERAH | C17: IRWAN | D17: 10 | E17: SET | F17: 120000 | G17: =SUM(F17*D17) -> 1200000 | H17: =SUM(G17:G31) -> 14425000 | I17: DESEMBER | K17: 15 | L17: 44354 | M17: LEO | N17: 2000000 | O17: GIRO TGL 15/11/21
B18: SARUNG STIR DRD HITAM-ABU | C18: IRWAN | D18: 5 | E18: SET | F18: 120000 | G18: =SUM(F18*D18) -> 600000 | K18: 16 | L18: 44354 | M18: KO AKHON | N18: 12000000 | O18: LUNAS TF. TGL 29/10/21 | Q18: V | R18: =N7+N17 -> 5900000
B19: SARUNG STIR DRD HITAM-CREAM | C19: IRWAN | D19: 5 | E19: SET | F19: 120000 | G19: =SUM(F19*D19) -> 600000 | K19: 17 | L19: 44355 | M19: KO AKHON | N19: 3300000
B20: SARUNG STIR DRD HITAM-COKLAT | C20: IRWAN | D20: 5 | E20: SET | F20: 120000 | G20: =SUM(F20*D20) -> 600000 | K20: 18 | L20: 44361 | M20: KO AKHON | N20: 4000000
B21: SARUNG STIR DRD HITAM-POLOS | C21: IRWAN | D21: 5 | E21: SET | F21: 120000 | G21: =SUM(F21*D21) -> 600000 | K21: 19 | L21: 44365 | M21: HERMAN | N21: 8600000 | O21: GIRO TGL 10/11/21
B22: KAKI RAK BAGASI AUTO BOY | C22: IRWAN | D22: 2 | E22: SET | F22: 620000 | G22: =SUM(F22*D22) -> 1240000 | K22: 20 | L22: 44372 | M22: JSL | N22: 9475000 | O22: GIRO TGL 10/11/21 | Q22: V
B23: TRUNKLID PAJERO'16 HITAM | C23: IRWAN | D23: 5 | E23: SET | F23: 1000000 | G23: =SUM(F23*D23) -> 5000000 | K23: 21 | L23: 44411 | M23: TJM | N23: 18500000 | O23: LUNAS TF. TGL 06/11/21
B24: LAMPU HID I-CONCEPT 3 WARNA H4 | C24: IRWAN | D24: 3 | E24: SET | F24: 475000 | G24: =SUM(F24*D24) -> 1425000 | K24: 22 | L24: 44487 | M24: HERMAN(PINJAMAN) | N24: 15000000 | O24: GIRO 30/11/21
B25: ANTENA SIRIP HIU HYBRID MERAH | C25: IRWAN | D25: 5 | E25: SET | F25: 45000 | G25: =SUM(F25*D25) -> 225000 | K25: 23 | L25: 44517 | M25: HENDRIK | N25: 4845000 | O25: LUNAS CASH 29/11
B26: EMBLEM CUP MESIN XPANDER CROSS CHROME | C26: IRWAN | D26: 10 | E26: SET | F26: 120000 | G26: =SUM(F26*D26) -> 1200000
B27: OUTHER HITAM XPANDER | C27: IRWAN | D27: 5 | E27: SET | F27: 95000 | G27: =SUM(F27*D27) -> 475000 | M27: TOTAL | N27: =SUM(N3:N26) -> 161017000
B28: HANDLE HITAM XPANDER | C28: IRWAN | D28: 5 | E28: SET | F28: 85000 | G28: =SUM(F28*D28) -> 425000
B29: ANTENA SIRIP HIU HYBRID SILVER | C29: IRWAN | D29: 7 | E29: SET | F29: 45000 | G29: =SUM(F29*D29) -> 315000 | M29: DI BYR DG GIRO | N29: =N4+N5+N6+N7+N8+N10+N12+N13+N14+N16+N17+N21+N22+N24 -> 91472000
B30: BHOLAM STANDAR H11 55 WATT | C30: IRWAN | D30: 10 | E30: SET | F30: 25000 | G30: =SUM(F30*D30) -> 250000 | M30: LUNAS CASH/TF | N30: =N3+N9+N11+N15+N18+N19+N20+N23+N25 -> 69545000
B31: BHOLAM STANDAR H16 19 WATT | C31: IRWAN | D31: 10 | E31: SET | F31: 27000 | G31: =SUM(F31*D31) -> 270000
A32: 44385 | B32: BANTALAN LEHER RAIZE | C32: TOLIB | D32: 2 | E32: SET | F32: 0 | G32: 0 | H32: 0
A33: 44385 | B33: KARPET MOBIL FULL 360 1 LAPIS ALL NEW PAJERO '16 TYPE D | C33: MR. BOSS | D33: 1 | E33: SET | F33: 1790000 | G33: =F33*D33 -> 1790000 | H33: =SUM(G33) -> 1790000 | I33: TITIPAN MR BOSS KE ARAW
A34: 44387 | B34: CM ORCA RC-185-2F KOTAK INFRA RED TWO FUNCTION | C34: ORCA | D34: 20 | E34: PCS | F34: 100000 | G34: =D34*F34 -> 2000000 | H34: =SUM(G34) -> 2000000 | I34: DESEMBER (PERTENGAHAN) | N34: =SUM(N29:N30) -> 161017000
A35: 44389 | B35: TANDUK+ BRAKET RUSH '18 DELUXE | C35: IRWAN | D35: 5 | E35: SET | F35: 730000 | G35: =D35*F35 -> 3650000 | H35: =SUM(G35:G37) -> 5825000 | I35: DESEMBER (AKHIR)
B36: ANTENA SIRIP HIU HYBRID HITAM | C36: IRWAN | D36: 5 | E36: \P | F36: 45000 | G36: =D36*F36 -> 225000 | M36: KO AKHON 4.5 BLN
B37: TALANG AIR FLAT CITY HB | C37: IRWAN | D37: 15 | E37: ;[LK | F37: 130000 | G37: =D37*F37 -> 1950000
A38: 44396 | B38: BODY KIT CITY HB MODULO DESIGN | C38: OTOPROJECT | D38: 2 | E38: SET | F38: 2699000 | G38: =D38*F38 -> 5398000 | H38: =SUM(G38:G43) -> 10305000 | I38: SEPTEMBER
B39: DOOR SILT PLATE CITY HB W/LAMP ORI DESIGN | C39: OTOPROJECT | D39: 2 | E39: SET | F39: 425000 | G39: =D39*F39 -> 850000
B40: MUFFLER CUTTER PAJERO'16 | C40: OTOPROJECT | D40: 5 | E40: SET | F40: 150000 | G40: =D40*F40 -> 750000
...

Sheet AGUSTUS
A1: BARANG MASUK ARAW FILM | K1: BON JATUH TEMPO DESEMBER 2021 ( JT)
A2: TGL MASUK | B2: NAMA BARANG | C2: SUPLIER | D2: QTY | E2: SAT | F2: HARGA/PCS/SET | G2: JUMLAH | H2: TOTAL FAKTUR | I2: KET | K2: NO | L2: TGL BARANG MASUK | M2: NAMA SALES/ SUPLIER | N2: JUMLAH BON | O2: KET
A3: 44410 | B3: KARPET DASAR JAZZ'19 HITAM TIPIS | C3: HERMAN | D3: 20 | E3: SET | F3: 145000 | G3: =F3*D3 -> 2900000 | H3: =SUM(G3) -> 2900000 | I3: JANUARI | K3: 1 | L3: 44354 | M3: IRWAN | N3: 10000000 | O3: GIRO TGL 15/12/21
A4: 44410 | B4: KERANDA | C4: JAYA MADANI | D4: 1 | E4: SET | F4: 3600000 | G4: =F4*D4 -> 3600000 | H4: =SUM(G4) -> 3600000 | I4: AGUSTUS ( AKHIR) | K4: 2 | L4: 44361 | M4: IRWAN | N4: 7070000 | R4: =960/120 -> 8
A5: 44411 | B5: KARPET DASAR SUPER BRIO HITAM | C5: NU (TOLIB) | D5: 5 | E5: SET | F5: 150000 | G5: =F5*D5 -> 750000 | H5: =SUM(G5:G6) -> 1500000 | I5: LUNAS 26/7/21 (AGUSTUS) | K5: 3 | L5: 44368 | M5: IRWAN | N5: 1320000
B6: KARPET DASAR SUPER HITAM CITY HAUS BEK | C6: NU (TOLIB) | D6: 5 | E6: SET | F6: 150000 | G6: =F6*D6 -> 750000 | K6: 4 | L6: 44375 | M6: IRWAN | N6: 2400000
A7: 44411 | B7: SUPERLID D/C HILUX REVO +KIT | C7: TJM | D7: 1 | E7: SET | F7: 18500000 | G7: =F7*D7 -> 18500000 | H7: =SUM(G7) -> 18500000 | I7: NOVEMBER | K7: 5 | L7: 44378 | M7: AM77 | N7: 4400000 | O7: GIRO TGL 15/12/21 | S7: =SUM(AGUSTUS!N7+AGUSTUS!N8+AGUSTUS!N12) -> 13080000
A8: 44411 | B8: LAMPU POLISI LED MERAH | C8: IRWAN | D8: 1 | E8: SET | F8: 2900000 | G8: =F8*D8 -> 2900000 | H8: =SUM(G8) -> 2900000 | I8: JANUARI | K8: 6 | L8: 44383 | M8: AM77 | N8: 5720000 | O8: GIRO TGL 15/12/21
A9: 44411 | B9: KARPET DASAR AN BRIO TIPTS | C9: HERMAN | D9: 30 | E9: SET | F9: 150000 | G9: =F9*D9 -> 4500000 | H9: =SUM(G9) -> 4500000 | I9: JANUARI | K9: 7 | L9: 44385 | M9: IRWAN | N9: 14425000 | O9: GIRO TGL 15/12/21 | Q9: 3600
A10: 44413 | B10: SARUNG JOK BRIO SATYA H/M | C10: BUK IDA | D10: 1 | E10: SET | F10: 0 | G10: =F10*D10 -> 0 | H10: =SUM(G10) -> 0 | K10: 8 | L10: 44387 | M10: ORCA | N10: 2000000 | O10: GIRO TGL 30/12/21 | Q10: 960
A11: 44414 | B11: KARPET DASAR BRIO HITAM TIPIS | C11: HERMAN | D11: 30 | E11: SET | F11: 150000 | G11: =F11*D11 -> 4500000 | H11: =SUM(G11:G12) -> 9000000 | I11: JANUARI | K11: 9 | L11: 44389 | M11: IRWAN | N11: 5825000 | O11: GIRO TGL 15/12/21 | Q11: 1400
B12: KARPET DASAR JAZZ'19 HITAM TIPIS | C12: HERMAN | D12: 30 | E12: SET | F12: 150000 | G12: =F12*D12 -> 4500000 | K12: 10 | L12: 44398 | M12: AM77 | N12: 2960000 | O12: GIRO TGL 15/12/21
A13: 44415 | B13: GRILLE PAJERO '21 MODEL ALPHARD | C13: IRWAN | D13: 1 | E13: SET | F13: 1300000 | G13: =F13*D13 -> 1300000 | H13: =SUM(G13:G15) -> 4950000 | I13: JANUARI | K13: 11 | L13: 44404 | M13: IRWAN | N13: 3670000 | O13: GIRO TGL 15/12/21 | Q13: =SUM(Q9:Q12) -> 5960
B14: TANDUK +BREKET AVANZA'19 DELEXU | C14: IRWAN | D14: 5 | E14: SET | F14: 730000 | G14: =F14*D14 -> 3650000 | K14: 12 | L14: 44421 | M14: MR BOSS | N14: 750000 | O14: GIRO TGL 30/12/21 | S14: =AGUSTUS!N4+AGUSTUS!N5+AGUSTUS!N6+AGUSTUS!N9+AGUSTUS!N11+AGUSTUS!N13+AGUSTUS!N3 -> 44710000
B15: TANDUK +BREKET RUSH'19 DELEXU | C15: IRWAN | D15: 1 | E15: SET | F15: BONUS | K15: 13 | L15: 44400 | M15: ORCA | N15: 150000 | O15: GIRO . TGL 30/12/21
A16: 44415 | B16: EMBLEM CUP MESIN PAJERO SPORT CHROME | C16: IRWAN | D16: 8 | E16: SET | F16: 120000 | G16: =F16*D16 -> 960000 | H16: =SUM(G16) -> 960000 | I16: MARET | K16: 14 | L16: 44464 | M16: MR BOSS | N16: 14645000 | O16: GIRO TGL 30/12/21
A17: 44415 | B17: EMBLEM RS ORI GRILL DEPAN | C17: HERMAN | D17: 5 | E17: PCS | F17: RETUR TDK COCOK | G17: 0 | H17: =SUM(G17:G29) -> 2225000 | I17: JANUARI | K17: 15 | L17: 44481 | M17: OTOPROJECT | N17: 3518400 | O17: LUNAS TF. TGL 2/12/21 | Q17: =AGUSTUS!N14+AGUSTUS!N16+AGUSTUS!N19 -> 16175000
B18: COLOKAN SEAT BELT DOUBLE HONDA | C18: HERMAN | D18: 12 | E18: PCS | F18: 45000 | G18: =D18*F18 -> 540000 | K18: 16 | L18: 44483 | M18: TJM | N18: 11190000 | O18: GIRO TGL 25/12/21 | Q18: =SUM(AGUSTUS!N14+AGUSTUS!N16) -> 15395000
B19: COLOKAN SEAT BELT DOUBLE TOYOTA | C19: HERMAN | D19: 8 | E19: PCS | F19: 45000 | G19: =D19*F19 -> 360000 | K19: 17 | L19: 44459 | M19: MR BOSS | N19: 780000 | O19: GIRO TGL 30/12/21
B20: EMBLEM CUP MENSIN XPANDER CHROME | C20: HERMAN | D20: 10 | E20: SET | F20: 82500 | G20: =D20*F20 -> 825000 | K20: 18 | L20: 44487 | M20: HERMAN (PINJAMAN) | N20: 15000000 | O20: GIRO TGL 12/12/21
B21: SILIKON KUNCI HONDA BRIO HITAM | C21: HERMAN | D21: 10 | E21: PCS | F21: 10000 | G21: =D21*F21 -> 100000 | K21: 19 | L21: 44498 | M21: V-CENT | N21: 2100000 | O21: LUNAS TF. TGL 04/01/22 | S21: =44*200 -> 8800
B22: SILIKON KUNCI HONDA BRIO MERAH | C22: HERMAN | D22: 6 | E22: PCS | F22: 10000 | G22: =D22*F22 -> 60000 | K22: 20 | L22: 44515 | M22: V-CENT | N22: 3200000 | Q22: =SUM(N21:N22) -> 5300000
B23: SILIKON KUNCI HONDA BRIO BIRU | C23: HERMAN | D23: 4 | E23: PCS | F23: 10000 | G23: =D23*F23 -> 40000 | K23: 21 | L23: 44512 | M23: JAYA MADANI | N23: 7200000 | O23: LUNAS TF
B24: SILIKON KUNCI TOYOTA RUSH/VELOZ HITAM | C24: HERMAN | D24: 10 | E24: PCS | F24: 10000 | G24: =D24*F24 -> 100000 | K24: 22 | L24: 44539 | M24: WINCOS | N24: 29800000 | O24: LUNAS TF. TGL 29/12/21
B25: SILIKON KUNCI TOYOTA RUSH/VELOZ MERAH | C25: HERMAN | D25: 6 | E25: PCS | F25: 10000 | G25: =D25*F25 -> 60000 | K25: 23 | L25: 44551 | M25: HENDRIK | N25: 4892500 | O25: LUNAS TF. 06/01/22 | Q25: 4892500
B26: SILIKON KUNCI TOYOTA RUSH/VELOZ BIRU | C26: HERMAN | D26: 4 | E26: PCS | F26: 10000 | G26: =D26*F26 -> 40000
B27: SILIKON KUNCI TOYOTA 3 TOMBOL ALL NEW FORTUNER HITAM | C27: HERMAN | D27: 5 | E27: PCS | F27: 10000 | G27: =D27*F27 -> 50000 | M27: TOTAL | N27: =SUM(N3:N26) -> 153015900
B28: SILIKON KUNCI TOYOTA 3 TOMBOL ALL NEW FORTUNER MERAH | C28: HERMAN | D28: 3 | E28: PCS | F28: 10000 | G28: =D28*F28 -> 30000
B29: SILIKON KUNCI TOYOTA 3 TOMBOL ALL NEW FORTUNER BIRU | C29: HERMAN | D29: 2 | E29: PCS | F29: 10000 | G29: =D29*F29 -> 20000
A30: 44415 | B30: KACA FILM PREMIUM HCD 03 G 2107010017K2A8 | C30: WINCOS | D30: 1 | E30: ROL | F30: 19800000 | G30: =D30*F30 -> 19800000 | H30: =SUM(G30:G31) -> 39600000 | I30: LUNAS TGL 30/8/21
B31: KACA FILM PREMIUM HCD 20 G 2107010046K2AA | C31: WINCOS | D31: 1 | E31: ROL | F31: 19800000 | G31: =D31*F31 -> 19800000 | M31: GIRO | N31: =N3+N4+N5+N6+N7+N8+N9+N10+N11+N12+N13+N14+N15+N16+N18+N19+N20 -> 102305000
A32: 44417 | B32: TOWING RUSH/TERIOS MCC | C32: GREAT | D32: 10 | E32: SET | F32: 1200000 | G32: =D32*F32 -> 12000000 | H32: =SUM(G32) -> 12000000 | I32: JANUARI
A33: 44420 | B33: TRUNKLID FORTUNER LED | C33: GREAT | D33: 10 | E33: SET | F33: 900000 | G33: =D33*F33 -> 9000000 | H33: =SUM(G33) -> 9000000 | I33: JANUARI
A34: 44421 | B34: SARUNG JOK BRIO SATYA MB TECK(9001+9005) | C34: BUK IDA | D34: 1 | E34: SET | F34: 0 | G34: =D34*F34 -> 0 | H34: 0
A35: 44421 | B35: SILT PLATE BELAKANG INNOVA'16 | C35: MR.BOSS | D35: 5 | E35: SET | F35: 150000 | G35: =D35*F35 -> 750000 | H35: =SUM(G35) -> 750000 | I35: DESEMBER
A36: 44424 | B36: FOGLAMP RUSH '18 | C36: IRWAN | D36: 4 | E36: SET | F36: 450000 | G36: =F36*D36 -> 1800000 | H36: =SUM(G36) -> 1800000 | I36: PENGGANTI BARANG
A37: 44424 | B37: TRANK LID ALL NEW FORTUNER + LAMPU RING | C37: IRWAN | D37: 10 | E37: SET | F37: 1000000 | G37: =F37*D37 -> 10000000 | H37: =SUM(G37) -> 10000000 | I37: APRIL
A38: 44424 | B38: OUTER ALL NEW PAJERO HITAM | C38: IRWAN | D38: 10 | E38: SET | F38: 95000 | G38: =D38*F38 -> 950000 | H38: =SUM(G38:G42) -> 10550000 | I38: JANUARI
B39: HANDLE ALL NEW RUSH '18 HITAM | C39: IRWAN | D39: 10 | E39: SET | F39: 85000 | G39: =D39*F39 -> 850000
B40: TANK COVER KARBON CALYA | C40: IRWAN | D40: 5 | E40: SET | F40: 50000 | G40: =D40*F40 -> 250000
...

Sheet SEPTEMBER
A1: BARANG MASUK ARAW FILM | K1: BON JATUH TEMPO JANUARI 2022 ( JT)
A2: TGL MASUK | B2: NAMA BARANG | C2: SUPLIER | D2: QTY | E2: SAT | F2: HARGA/PCS/SET | G2: JUMLAH | H2: TOTAL FAKTUR | I2: KET | K2: NO | L2: TGL BARANG MASUK | M2: NAMA SALES/ SUPLIER | N2: JUMLAH BON | O2: KET
A3: 44441 | B3: SARUNG STIR JEWEL HITAM BENANG MERAH | C3: IRWAN | D3: 10 | E3: SET | F3: 120000 | G3: =F3*D3 -> 1200000 | H3: =SUM(G3:G6) -> 3600000 | I3: MARET | K3: 1 | L3: 44404 | M3: IRWAN | N3: 9900000 | O3: GIRO TGL 20/1/22
B4: SARUNG STIR JEWEL HITAM MERAH HITAM | C4: IRWAN | D4: 10 | E4: SET | F4: 120000 | G4: =F4*D4 -> 1200000 | K4: 2 | L4: 44410 | M4: HERMAN | N4: 3000000 | O4: GIRO TGL 30/01/2022
